<?xml version="1.0" encoding="utf-8"?>
<!-- =================================================================================== -->
<!-- |    This document was autogenerated by xacro from robot.xacro                    | -->
<!-- |    EDITING THIS FILE BY HAND IS NOT RECOMMENDED                                 | -->
<!-- =================================================================================== -->
<robot name="robot">
  <!-- <xacro:arg name="camera_visual" default="false"/> -->
  <material name="black">
    <color rgba="0.0 0.0 0.0 1.0"/>
  </material>
  <material name="blue">
    <color rgba="0.0 0.0 0.8 1.0"/>
  </material>
  <material name="green">
    <color rgba="0.0 0.8 0.0 1.0"/>
  </material>
  <material name="grey">
    <color rgba="0.2 0.2 0.2 1.0"/>
  </material>
  <material name="grey_alpha">
    <color rgba="0.2 0.2 0.2 0.5"/>
  </material>
  <material name="silver">
    <color rgba="0.913725490196 0.913725490196 0.847058823529 1.0"/>
  </material>
  <material name="orange">
    <color rgba="1.0 0.423529411765 0.0392156862745 1.0"/>
  </material>
  <material name="orange_alpha">
    <color rgba="1.0 0.423529411765 0.0392156862745 0.85"/>
  </material>
  <material name="brown">
    <color rgba="0.870588235294 0.811764705882 0.764705882353 1.0"/>
  </material>
  <material name="red">
    <color rgba="0.8 0.0 0.0 1.0"/>
  </material>
  <material name="white">
    <color rgba="1.0 1.0 1.0 1.0"/>
  </material>
  <!-- ros_control plugin -->
  <gazebo>
    <plugin filename="liblegged_hw_sim.so" name="gazebo_ros_control">
      <robotNamespace>/</robotNamespace>
      <robotParam>legged_robot_description</robotParam>
      <robotSimType>legged_gazebo/QuadHWSim</robotSimType>
    </plugin>
  </gazebo>
  <gazebo>
    <plugin filename="libgazebo_ros_p3d.so" name="p3d_base_controller">
      <alwaysOn>true</alwaysOn>
      <updateRate>1000.0</updateRate>
      <bodyName>base</bodyName>
      <topicName>ground_truth/state</topicName>
      <gaussianNoise>0</gaussianNoise>
      <frameName>world</frameName>
      <xyzOffsets>0 0 0</xyzOffsets>
      <rpyOffsets>0 0 0</rpyOffsets>
    </plugin>
  </gazebo>
  <gazebo reference="base">
    <maxVel>100.</maxVel>
    <material>Gazebo/Grey</material>
    <kp>10000.</kp>
    <kd>0.</kd>
  </gazebo>
  <!-- <gazebo reference="stick_link">
        <mu1>0.2</mu1>
        <mu2>0.2</mu2>
        <material>Gazebo/White</material>
    </gazebo> -->
  <!-- LF leg -->
  <gazebo reference="LF_HIP">
    <mu1>0.2</mu1>
    <mu2>0.2</mu2>
    <material>Gazebo/DarkGrey</material>
  </gazebo>
  <gazebo reference="LF_THIGH">
    <mu1>0.2</mu1>
    <mu2>0.2</mu2>
    <self_collide>1</self_collide>
    <material>Gazebo/DarkGrey</material>
    <kp value="1000000.0"/>
    <kd value="1.0"/>
  </gazebo>
  <gazebo reference="LF_SHANK">
    <mu1>0.2</mu1>
    <mu2>0.2</mu2>
    <self_collide>1</self_collide>
    <material>Gazebo/Orange</material>
  </gazebo>
  <gazebo reference="LF_FOOT">
    <mu1>0.6</mu1>
    <mu2>0.6</mu2>
    <self_collide>1</self_collide>
    <material>Gazebo/DarkGrey</material>
    <kp value="1000000.0"/>
    <kd value="100.0"/>
  </gazebo>
  <!-- RF leg -->
  <gazebo reference="RF_HIP">
    <mu1>0.2</mu1>
    <mu2>0.2</mu2>
    <material>Gazebo/DarkGrey</material>
  </gazebo>
  <gazebo reference="RF_THIGH">
    <mu1>0.2</mu1>
    <mu2>0.2</mu2>
    <self_collide>1</self_collide>
    <material>Gazebo/DarkGrey</material>
    <kp value="1000000.0"/>
    <kd value="1.0"/>
  </gazebo>
  <gazebo reference="RF_SHANK">
    <mu1>0.2</mu1>
    <mu2>0.2</mu2>
    <self_collide>1</self_collide>
    <material>Gazebo/Orange</material>
  </gazebo>
  <gazebo reference="RF_FOOT">
    <mu1>0.6</mu1>
    <mu2>0.6</mu2>
    <self_collide>1</self_collide>
    <material>Gazebo/DarkGrey</material>
    <kp value="1000000.0"/>
    <kd value="100.0"/>
  </gazebo>
  <!-- LH leg -->
  <gazebo reference="LH_HIP">
    <mu1>0.2</mu1>
    <mu2>0.2</mu2>
    <material>Gazebo/DarkGrey</material>
  </gazebo>
  <gazebo reference="LH_THIGH">
    <mu1>0.2</mu1>
    <mu2>0.2</mu2>
    <self_collide>1</self_collide>
    <material>Gazebo/DarkGrey</material>
    <kp value="1000000.0"/>
    <kd value="1.0"/>
  </gazebo>
  <gazebo reference="LH_SHANK">
    <mu1>0.2</mu1>
    <mu2>0.2</mu2>
    <self_collide>1</self_collide>
    <material>Gazebo/Orange</material>
  </gazebo>
  <gazebo reference="LH_FOOT">
    <mu1>0.6</mu1>
    <mu2>0.6</mu2>
    <self_collide>1</self_collide>
    <material>Gazebo/DarkGrey</material>
    <kp value="1000000.0"/>
    <kd value="100.0"/>
  </gazebo>
  <!-- RH leg -->
  <gazebo reference="RH_HIP">
    <mu1>0.2</mu1>
    <mu2>0.2</mu2>
    <material>Gazebo/DarkGrey</material>
  </gazebo>
  <gazebo reference="RH_THIGH">
    <mu1>0.2</mu1>
    <mu2>0.2</mu2>
    <self_collide>1</self_collide>
    <material>Gazebo/DarkGrey</material>
    <kp value="1000000.0"/>
    <kd value="1.0"/>
  </gazebo>
  <gazebo reference="RH_SHANK">
    <mu1>0.2</mu1>
    <mu2>0.2</mu2>
    <self_collide>1</self_collide>
    <material>Gazebo/Orange</material>
  </gazebo>
  <gazebo reference="RH_FOOT">
    <mu1>0.6</mu1>
    <mu2>0.6</mu2>
    <self_collide>1</self_collide>
    <material>Gazebo/DarkGrey</material>
    <kp value="1000000.0"/>
    <kd value="100.0"/>
  </gazebo>
  <!-- <gazebo reference="camera_rgb_frame">
    <sensor type="depth" name="realsense_R200">
      <always_on>true</always_on>
      <visualize>$(arg camera_visual)</visualize>
      <camera>
          <horizontal_fov>1.3439</horizontal_fov>
          <image>
              <width>1920</width>
              <height>1080</height>
              <format>R8G8B8</format>
          </image>
          <depth_camera></depth_camera>
          <clip>
              <near>0.03</near>
              <far>100</far>
          </clip>
      </camera>
      <plugin name="camera_controller" filename="libgazebo_ros_openni_kinect.so">
        <baseline>0.2</baseline>
        <alwaysOn>true</alwaysOn>
        <updateRate>30.0</updateRate>
        <cameraName>camera</cameraName>
        <frameName>camera_rgb_optical_frame</frameName>
        <imageTopicName>rgb/image_raw</imageTopicName>
        <depthImageTopicName>depth/image_raw</depthImageTopicName>
        <pointCloudTopicName>depth/points</pointCloudTopicName>
        <cameraInfoTopicName>rgb/camera_info</cameraInfoTopicName>
        <depthImageCameraInfoTopicName>depth/camera_info</depthImageCameraInfoTopicName>
        <pointCloudCutoff>0.4</pointCloudCutoff>
            <hackBaseline>0.07</hackBaseline>
            <distortionK1>0.0</distortionK1>
            <distortionK2>0.0</distortionK2>
            <distortionK3>0.0</distortionK3>
            <distortionT1>0.0</distortionT1>
            <distortionT2>0.0</distortionT2>
        <CxPrime>0.0</CxPrime>
        <Cx>0.0</Cx>
        <Cy>0.0</Cy>
        <focalLength>0</focalLength>
        <hackBaseline>0</hackBaseline>
      </plugin>
    </sensor>
  </gazebo> -->
  <link name="base">
    <visual>
      <origin rpy="0 0 0" xyz="0 0 0"/>
      <geometry>
        <mesh filename="package://freeAny_description/meshes/base.STL" scale="1 1 1"/>
      </geometry>
      <material name="orange"/>
    </visual>
    <collision>
      <origin rpy="0 0 0" xyz="0 0 0"/>
      <geometry>
        <box size="0.3504 0.18 0.14"/>
      </geometry>
    </collision>
    <inertial>
      <origin rpy="0 0 0" xyz="0.0036585 0.0 -0.0077332"/>
      <mass value="4.71"/>
      <inertia ixx="0.02327755" ixy="3.3511e-05" ixz="0.000186233" iyy="0.126017746" iyz="-1.4056e-05" izz="0.133811568"/>
    </inertial>
  </link>
  <joint name="base_to_battery" type="fixed">
    <origin rpy="0 0 0" xyz="-0.0945 0 -0.006"/>
    <parent link="base"/>
    <child link="battery"/>
    <axis xyz="0 0 0"/>
  </joint>
  <gazebo reference="base_to_battery">
    <disableFixedJointLumping>true</disableFixedJointLumping>
  </gazebo>
  <link name="battery">
    <inertial>
      <origin rpy="0 0 0" xyz="0 4.0915E-05 3.0102E-05"/>
      <mass value="1.47"/>
      <inertia ixx="0.004712212" ixy="-1.6E-08" ixz="-8.0E-09" iyy="0.001037398" iyz="3.622E-06" izz="0.004615705"/>
    </inertial>
    <visual>
      <origin rpy="0 0 0" xyz="0 0 0"/>
      <geometry>
        <mesh filename="package://freeAny_description/meshes/battery.STL"/>
      </geometry>
      <material name="orange"/>
    </visual>
  </link>
  <!-- Imu is fixed to the base link -->
  <joint name="yesense_imu_joint" type="fixed">
    <origin rpy="0. 0. 0." xyz="0.12095 0 -0.0335"/>
    <parent link="base"/>
    <child link="yesense_imu"/>
  </joint>
  <!-- Imu link -->
  <link name="yesense_imu">
    <inertial>
      <mass value="0.03"/>
      <origin rpy="0 0 0" xyz="0 0 -0.0072335"/>
      <inertia ixx="4.013E-06" ixy="0" ixz="-1.5E-08" iyy="6.158E-06" iyz="-2.0E-09" izz="6.061E-06"/>
    </inertial>
    <visual>
      <origin rpy="0 0 0" xyz="0 0 0"/>
      <geometry>
        <mesh filename="package://freeAny_description/meshes/IMU.STL"/>
      </geometry>
    </visual>
    <material name="orange">
      <color rgba="255 108 10 255"/>
    </material>
  </link>
  <gazebo reference="yesense_imu">
    <material>Gazebo/Orange</material>
  </gazebo>
  <gazebo reference="yesense_imu_joint">
    <disableFixedJointLumping>true</disableFixedJointLumping>
  </gazebo>
  <!-- lidar is fixed to the base link -->
  <joint name="base_to_BP_lidar_joint" type="fixed">
    <origin rpy="-1.5708 1.0472 -1.5708" xyz="0.38227 0 0"/>
    <parent link="base"/>
    <child link="BP_lidar"/>
  </joint>
  <!-- lidar link -->
  <link name="BP_lidar">
    <inertial>
      <mass value="1.0"/>
      <origin rpy="0 0 0" xyz="-0.00092658 3.0E-05 -0.058804"/>
      <inertia ixx="0.005077876" ixy="1.493E-06" ixz="7.8943E-05" iyy="0.005133860" iyz="-2.922E-06" izz="0.001777821"/>
    </inertial>
    <visual>
      <origin rpy="0 0 0" xyz="0 0 0"/>
      <geometry>
        <mesh filename="package://freeAny_description/meshes/BP_lidar.STL"/>
      </geometry>
      <material name="silver"/>
    </visual>
    <!-- <collision> 
                <origin rpy="0 0 0" xyz="0 0 0"/>
                <geometry>
                    <cylinder length="0.06" radius="0.045"/>
                </geometry>
            </collision>
            <collision>
                <origin rpy="0 0 0" xyz="0 0 0"/>
                <geometry>
                    <sphere radius="0.043"/>
                </geometry>
            </collision> -->
  </link>
  <gazebo reference="base_to_BP_lidar_joint">
    <disableFixedJointLumping>true</disableFixedJointLumping>
  </gazebo>
  <!-- lidar is fixed to the base link -->
  <joint name="base_to_realsense_camera_joint" type="fixed">
    <origin rpy="0 0.6 0" xyz="0.4 0 0.15"/>
    <parent link="base"/>
    <child link="realsense_camera"/>
  </joint>
  <!-- lidar link -->
  <link name="realsense_camera">
    <inertial>
      <mass value="0.01"/>
      <origin rpy="0 0 0" xyz="0 0 0"/>
      <inertia ixx="0.0000001" ixy="0" ixz="0" iyy="0.0000001" iyz="0" izz="0.0000001"/>
    </inertial>
    <!-- <visual>
                <origin xyz="0 0 0" rpy="0 0 0"/>
                <geometry>
                <mesh filename="package://turtlebot3_description/meshes/sensors/r200.dae" />
                </geometry>
                <material name = "silver" />
            </visual> -->
    <!-- <collision>
                <origin xyz="0.003 0.065 0.007" rpy="0 0 0"/>
                <geometry>
                    <box size="0.012 0.132 0.020"/>
                </geometry>
            </collision> -->
  </link>
  <joint name="camera_rgb_joint" type="fixed">
    <origin rpy="0 0 0" xyz="0.005 0.018 0.013"/>
    <parent link="realsense_camera"/>
    <child link="camera_rgb_frame"/>
  </joint>
  <link name="camera_rgb_frame">
    <inertial>
      <mass value="0.01"/>
      <origin rpy="0 0 0" xyz="0 0 0"/>
      <inertia ixx="0.0000001" ixy="0" ixz="0" iyy="0.0000001" iyz="0" izz="0.0000001"/>
    </inertial>
  </link>
  <joint name="camera_rgb_optical_joint" type="fixed">
    <origin rpy="-1.57 0 -1.57" xyz="0 0 0"/>
    <parent link="camera_rgb_frame"/>
    <child link="camera_rgb_optical_frame"/>
  </joint>
  <link name="camera_rgb_optical_frame"/>
  <joint name="camera_depth_joint" type="fixed">
    <origin rpy="0 0 0" xyz="0.005 0.028 0.013"/>
    <parent link="realsense_camera"/>
    <child link="camera_depth_frame"/>
  </joint>
  <link name="camera_depth_frame"/>
  <joint name="camera_depth_optical_joint" type="fixed">
    <origin rpy="-1.57 0 -1.57" xyz="0 0 0"/>
    <parent link="camera_depth_frame"/>
    <child link="camera_depth_optical_frame"/>
  </joint>
  <link name="camera_depth_optical_frame"/>
  <gazebo reference="base_to_realsense_camera_joint">
    <disableFixedJointLumping>true</disableFixedJointLumping>
  </gazebo>
  <gazebo reference="camera_rgb_frame">
    <sensor name="realsense_R200" type="depth">
      <always_on>true</always_on>
      <visualize>false</visualize>
      <camera>
        <horizontal_fov>1.3439</horizontal_fov>
        <image>
          <width>1920</width>
          <height>1080</height>
          <format>R8G8B8</format>
        </image>
        <depth_camera/>
        <clip>
          <near>0.03</near>
          <far>100</far>
        </clip>
      </camera>
      <plugin filename="libgazebo_ros_openni_kinect.so" name="camera_controller">
        <baseline>0.2</baseline>
        <alwaysOn>true</alwaysOn>
        <updateRate>30.0</updateRate>
        <cameraName>camera</cameraName>
        <frameName>camera_rgb_optical_frame</frameName>
        <imageTopicName>rgb/image_raw</imageTopicName>
        <depthImageTopicName>depth/image_raw</depthImageTopicName>
        <pointCloudTopicName>depth/points</pointCloudTopicName>
        <cameraInfoTopicName>rgb/camera_info</cameraInfoTopicName>
        <depthImageCameraInfoTopicName>depth/camera_info</depthImageCameraInfoTopicName>
        <pointCloudCutoff>0.4</pointCloudCutoff>
        <hackBaseline>0.07</hackBaseline>
        <distortionK1>0.0</distortionK1>
        <distortionK2>0.0</distortionK2>
        <distortionK3>0.0</distortionK3>
        <distortionT1>0.0</distortionT1>
        <distortionT2>0.0</distortionT2>
        <CxPrime>0.0</CxPrime>
        <Cx>0.0</Cx>
        <Cy>0.0</Cy>
        <focalLength>0</focalLength>
        <hackBaseline>0</hackBaseline>
      </plugin>
    </sensor>
  </gazebo>
  <!-- lr_val = 1(left)/-1(right) fh_val = 1(front)/-1(hind) -->
  <!-- <xacro:macro name="leg" params="prefix lr_val left_right fh_val front_hind *origin"> -->
  <joint name="LF_HAA" type="revolute">
    <origin rpy="0 0 0" xyz="0.1756 0.055 0"/>
    <parent link="base"/>
    <child link="LF_HIP"/>
    <axis xyz="1 0 0"/>
    <dynamics damping="0" friction="0"/>
    <limit effort="33.5" lower="-0.802851455917" upper="0.802851455917" velocity="21"/>
  </joint>
  <link name="LF_HIP">
    <visual>
      <origin rpy="0 0 0" xyz="0 0 0"/>
      <geometry>
        <mesh filename="package://freeAny_description/meshes/HIP.STL" scale="1 1 1"/>
      </geometry>
      <material name="grey"/>
    </visual>
    <collision>
      <origin rpy="1.57079632679 0 0" xyz="0.0541 0 0"/>
      <geometry>
        <cylinder length="0.04" radius="0.046"/>
      </geometry>
    </collision>
    <inertial>
      <origin rpy="0 0 0" xyz="0.042659 0.0034843 -0.00035303"/>
      <mass value="0.715"/>
      <inertia ixx="0.000546211" ixy="0.000114344" ixz="-1.0737e-05" iyy="0.002324487" iyz="3.2554e-05" izz="0.002086762"/>
    </inertial>
  </link>
  <joint name="LF_HIPFix" type="fixed">
    <origin rpy="0 0 0" xyz="0.08 0.04 0"/>
    <parent link="LF_HIP"/>
    <child link="LF_HIPFixed"/>
  </joint>
  <link name="LF_HIPFixed">
    <!-- <visual>
                <geometry>
                    <sphere radius="0.05"/>
                </geometry>
                <material name="red"/>
            </visual> -->
    <inertial>
      <origin rpy="0 0 0" xyz="0 0 0"/>
      <mass value="0.000001"/>
      <inertia ixx="0.00000001" ixy="0" ixz="0" iyy="0.00000001" iyz="0" izz="0.00000001"/>
    </inertial>
  </link>
  <joint name="LF_HFE" type="revolute">
    <origin rpy="0 0 1.57079632679" xyz="0.0541 0.09355 0"/>
    <parent link="LF_HIP"/>
    <child link="LF_THIGH"/>
    <axis xyz="1 0 0"/>
    <dynamics damping="0" friction="0"/>
    <limit effort="33.5" lower="-1.3962634016" upper="4.18879020479" velocity="21"/>
  </joint>
  <link name="LF_THIGH">
    <visual>
      <origin rpy="0 0 0" xyz="0 0 0"/>
      <geometry>
        <mesh filename="package://freeAny_description/meshes/thigh.STL" scale="1 1 1"/>
      </geometry>
      <material name="grey_alpha"/>
    </visual>
    <collision>
      <origin rpy="0 1.57079632679 0" xyz="-0.01 0 0"/>
      <geometry>
        <cylinder length="0.041" radius="0.032"/>
      </geometry>
    </collision>
    <collision>
      <origin rpy="0 0 0" xyz="0 0 -0.1"/>
      <geometry>
        <box size="0.032 0.048 0.2"/>
      </geometry>
    </collision>
    <inertial>
      <origin rpy="0 0 0" xyz="-0.018971 -0.0001 -0.072708"/>
      <mass value="1.15"/>
      <inertia ixx="0.014724523" ixy="5.677e-06" ixz="6.2711e-05" iyy="0.015466921" iyz="7.296e-06" izz="0.001822592"/>
    </inertial>
  </link>
  <joint name="LF_KFE" type="revolute">
    <origin rpy="0 0 0" xyz="0.034 0 -0.2"/>
    <parent link="LF_THIGH"/>
    <child link="LF_SHANK"/>
    <axis xyz="1 0 0"/>
    <dynamics damping="0" friction="0"/>
    <limit effort="52" lower="-3.14159265359" upper="3.14159265359" velocity="13"/>
  </joint>
  <link name="LF_SHANK">
    <visual>
      <origin rpy="0 0 0" xyz="0 0 0"/>
      <geometry>
        <mesh filename="package://freeAny_description/meshes/shank_Left.STL" scale="1 1 1"/>
      </geometry>
      <material name="grey"/>
    </visual>
    <collision>
      <origin rpy="0 0 0" xyz="0 -0.048 0"/>
      <geometry>
        <box size="0.03 0.02 0.045"/>
      </geometry>
    </collision>
    <collision>
      <origin rpy="0 1.57079632679 0" xyz="0 0 0"/>
      <geometry>
        <cylinder length="0.03" radius="0.029"/>
      </geometry>
    </collision>
    <inertial>
      <origin rpy="0 0 0" xyz="-0.000781 -0.029499 -0.004542"/>
      <mass value="0.085"/>
      <inertia ixx="0.000156178" ixy="0.0" ixz="0.0" iyy="3.8653e-05" iyz="1.8611e-05" izz="0.000133207"/>
    </inertial>
  </link>
  <joint name="shank_to_foot_LF" type="fixed">
    <origin rpy="0 0 -1.57079632679" xyz="0 -0.031301 -0.24819"/>
    <parent link="LF_SHANK"/>
    <child link="LF_FOOT"/>
  </joint>
  <link name="LF_FOOT">
    <visual>
      <origin rpy="0 0 0" xyz="0 0 0"/>
      <geometry>
        <mesh filename="package://freeAny_description/meshes/foot.STL" scale="1 1 1"/>
      </geometry>
      <material name="grey_alpha"/>
    </visual>
    <collision>
      <origin rpy="0 0 0" xyz="0.008 0 0.017"/>
      <geometry>
        <sphere radius="0.02"/>
      </geometry>
    </collision>
    <collision>
      <origin rpy="0 0 0" xyz="0.016 0 0.13125"/>
      <geometry>
        <cylinder length="0.21" radius="0.012"/>
      </geometry>
    </collision>
    <inertial>
      <origin rpy="0 0 0" xyz="0.012 0 0.065"/>
      <mass value="0.077"/>
      <inertia ixx="0.00629115" ixy="0.0" ixz="7.2557e-50" iyy="0.000641223" iyz="0" izz="2.3963e-05"/>
    </inertial>
  </link>
  <gazebo reference="shank_to_foot_LF">
    <disableFixedJointLumping>true</disableFixedJointLumping>
  </gazebo>
  <transmission name="LF_HAA_tran">
    <type>transmission_interface/SimpleTransmission</type>
    <joint name="LF_HAA">
      <hardwareInterface>hardware_interface/EffortJointInterface</hardwareInterface>
    </joint>
    <actuator name="LF_HAA_motor">
      <hardwareInterface>hardware_interface/EffortJointInterface</hardwareInterface>
      <mechanicalReduction>1</mechanicalReduction>
    </actuator>
  </transmission>
  <transmission name="LF_Thigh_tran">
    <type>transmission_interface/SimpleTransmission</type>
    <joint name="LF_HFE">
      <hardwareInterface>hardware_interface/EffortJointInterface</hardwareInterface>
    </joint>
    <actuator name="LF_Thigh_motor">
      <hardwareInterface>hardware_interface/EffortJointInterface</hardwareInterface>
      <mechanicalReduction>1</mechanicalReduction>
    </actuator>
  </transmission>
  <transmission name="LF_Knee_tran">
    <type>transmission_interface/SimpleTransmission</type>
    <joint name="LF_KFE">
      <hardwareInterface>hardware_interface/EffortJointInterface</hardwareInterface>
    </joint>
    <actuator name="LF_Knee_motor">
      <hardwareInterface>hardware_interface/EffortJointInterface</hardwareInterface>
      <mechanicalReduction>1</mechanicalReduction>
    </actuator>
  </transmission>
  <joint name="RF_HAA" type="revolute">
    <origin rpy="0 0 0" xyz="0.1756 -0.055 0"/>
    <parent link="base"/>
    <child link="RF_HIP"/>
    <axis xyz="1 0 0"/>
    <dynamics damping="0" friction="0"/>
    <limit effort="33.5" lower="-0.802851455917" upper="0.802851455917" velocity="21"/>
  </joint>
  <link name="RF_HIP">
    <visual>
      <origin rpy="3.14159265359 0 0" xyz="0 0 0"/>
      <geometry>
        <mesh filename="package://freeAny_description/meshes/HIP.STL" scale="1 1 1"/>
      </geometry>
      <material name="grey"/>
    </visual>
    <collision>
      <origin rpy="1.57079632679 0 0" xyz="0.0541 0 0"/>
      <geometry>
        <cylinder length="0.04" radius="0.046"/>
      </geometry>
    </collision>
    <inertial>
      <origin rpy="0 0 0" xyz="0.042659 -0.0034843 -0.00035303"/>
      <mass value="0.715"/>
      <inertia ixx="0.000546211" ixy="-0.000114344" ixz="-1.0737e-05" iyy="0.002324487" iyz="-3.2554e-05" izz="0.002086762"/>
    </inertial>
  </link>
  <joint name="RF_HIPFix" type="fixed">
    <origin rpy="0 0 0" xyz="0.08 -0.04 0"/>
    <parent link="RF_HIP"/>
    <child link="RF_HIPFixed"/>
  </joint>
  <link name="RF_HIPFixed">
    <!-- <visual>
                <geometry>
                    <sphere radius="0.05"/>
                </geometry>
                <material name="red"/>
            </visual> -->
    <inertial>
      <origin rpy="0 0 0" xyz="0 0 0"/>
      <mass value="0.000001"/>
      <inertia ixx="0.00000001" ixy="0" ixz="0" iyy="0.00000001" iyz="0" izz="0.00000001"/>
    </inertial>
  </link>
  <joint name="RF_HFE" type="revolute">
    <origin rpy="0 0 1.57079632679" xyz="0.0541 -0.09355 0"/>
    <parent link="RF_HIP"/>
    <child link="RF_THIGH"/>
    <axis xyz="1 0 0"/>
    <dynamics damping="0" friction="0"/>
    <limit effort="33.5" lower="-4.18879020479" upper="1.3962634016" velocity="21"/>
  </joint>
  <link name="RF_THIGH">
    <visual>
      <origin rpy="0 0 3.14159265359" xyz="0 0 0"/>
      <geometry>
        <mesh filename="package://freeAny_description/meshes/thigh.STL" scale="1 1 1"/>
      </geometry>
      <material name="grey_alpha"/>
    </visual>
    <collision>
      <origin rpy="0 1.57079632679 0" xyz="0.01 0 0"/>
      <geometry>
        <cylinder length="0.041" radius="0.032"/>
      </geometry>
    </collision>
    <collision>
      <origin rpy="0 0 0" xyz="0 0 -0.1"/>
      <geometry>
        <box size="0.032 0.048 0.2"/>
      </geometry>
    </collision>
    <inertial>
      <origin rpy="0 0 0" xyz="0.018971 0.0001 -0.072708"/>
      <mass value="1.15"/>
      <inertia ixx="0.014724523" ixy="5.677e-06" ixz="-6.2711e-05" iyy="0.015466921" iyz="-7.296e-06" izz="0.001822592"/>
    </inertial>
  </link>
  <joint name="RF_KFE" type="revolute">
    <origin rpy="0 0 0" xyz="-0.034 0 -0.2"/>
    <parent link="RF_THIGH"/>
    <child link="RF_SHANK"/>
    <axis xyz="1 0 0"/>
    <dynamics damping="0" friction="0"/>
    <limit effort="52" lower="-3.14159265359" upper="3.14159265359" velocity="13"/>
  </joint>
  <link name="RF_SHANK">
    <visual>
      <origin rpy="0 0 0" xyz="0 0 0"/>
      <geometry>
        <mesh filename="package://freeAny_description/meshes/shank_Right.STL" scale="1 1 1"/>
      </geometry>
      <material name="grey"/>
    </visual>
    <collision>
      <origin rpy="0 0 0" xyz="0 -0.048 0"/>
      <geometry>
        <box size="0.03 0.02 0.045"/>
      </geometry>
    </collision>
    <collision>
      <origin rpy="0 1.57079632679 0" xyz="0 0 0"/>
      <geometry>
        <cylinder length="0.03" radius="0.029"/>
      </geometry>
    </collision>
    <inertial>
      <origin rpy="0 0 0" xyz="0.000781 -0.029499 -0.004542"/>
      <mass value="0.085"/>
      <inertia ixx="0.000156178" ixy="-0.0" ixz="-0.0" iyy="3.8653e-05" iyz="1.8611e-05" izz="0.000133207"/>
    </inertial>
  </link>
  <joint name="shank_to_foot_RF" type="fixed">
    <origin rpy="0 0 -1.57079632679" xyz="0 -0.031301 -0.24819"/>
    <parent link="RF_SHANK"/>
    <child link="RF_FOOT"/>
  </joint>
  <link name="RF_FOOT">
    <visual>
      <origin rpy="0 0 0" xyz="0 0 0"/>
      <geometry>
        <mesh filename="package://freeAny_description/meshes/foot.STL" scale="1 1 1"/>
      </geometry>
      <material name="grey_alpha"/>
    </visual>
    <collision>
      <origin rpy="0 0 0" xyz="0.008 0 0.017"/>
      <geometry>
        <sphere radius="0.02"/>
      </geometry>
    </collision>
    <collision>
      <origin rpy="0 0 0" xyz="0.016 0 0.13125"/>
      <geometry>
        <cylinder length="0.21" radius="0.012"/>
      </geometry>
    </collision>
    <inertial>
      <origin rpy="0 0 0" xyz="0.012 0 0.065"/>
      <mass value="0.077"/>
      <inertia ixx="0.00629115" ixy="0.0" ixz="7.2557e-50" iyy="0.000641223" iyz="0" izz="2.3963e-05"/>
    </inertial>
  </link>
  <gazebo reference="shank_to_foot_RF">
    <disableFixedJointLumping>true</disableFixedJointLumping>
  </gazebo>
  <transmission name="RF_HAA_tran">
    <type>transmission_interface/SimpleTransmission</type>
    <joint name="RF_HAA">
      <hardwareInterface>hardware_interface/EffortJointInterface</hardwareInterface>
    </joint>
    <actuator name="RF_HAA_motor">
      <hardwareInterface>hardware_interface/EffortJointInterface</hardwareInterface>
      <mechanicalReduction>1</mechanicalReduction>
    </actuator>
  </transmission>
  <transmission name="RF_Thigh_tran">
    <type>transmission_interface/SimpleTransmission</type>
    <joint name="RF_HFE">
      <hardwareInterface>hardware_interface/EffortJointInterface</hardwareInterface>
    </joint>
    <actuator name="RF_Thigh_motor">
      <hardwareInterface>hardware_interface/EffortJointInterface</hardwareInterface>
      <mechanicalReduction>1</mechanicalReduction>
    </actuator>
  </transmission>
  <transmission name="RF_Knee_tran">
    <type>transmission_interface/SimpleTransmission</type>
    <joint name="RF_KFE">
      <hardwareInterface>hardware_interface/EffortJointInterface</hardwareInterface>
    </joint>
    <actuator name="RF_Knee_motor">
      <hardwareInterface>hardware_interface/EffortJointInterface</hardwareInterface>
      <mechanicalReduction>1</mechanicalReduction>
    </actuator>
  </transmission>
  <joint name="LH_HAA" type="revolute">
    <origin rpy="0 0 0" xyz="-0.1756 0.055 0"/>
    <parent link="base"/>
    <child link="LH_HIP"/>
    <axis xyz="1 0 0"/>
    <dynamics damping="0" friction="0"/>
    <limit effort="33.5" lower="-0.802851455917" upper="0.802851455917" velocity="21"/>
  </joint>
  <link name="LH_HIP">
    <visual>
      <origin rpy="0 3.14159265359 0" xyz="0 0 0"/>
      <geometry>
        <mesh filename="package://freeAny_description/meshes/HIP.STL" scale="1 1 1"/>
      </geometry>
      <material name="grey"/>
    </visual>
    <collision>
      <origin rpy="1.57079632679 0 0" xyz="0.0541 0 0"/>
      <geometry>
        <cylinder length="0.04" radius="0.046"/>
      </geometry>
    </collision>
    <inertial>
      <origin rpy="0 0 0" xyz="-0.042659 0.0034843 -0.00035303"/>
      <mass value="0.715"/>
      <inertia ixx="0.000546211" ixy="-0.000114344" ixz="1.0737e-05" iyy="0.002324487" iyz="3.2554e-05" izz="0.002086762"/>
    </inertial>
  </link>
  <joint name="LH_HIPFix" type="fixed">
    <origin rpy="0 0 0" xyz="-0.08 0.04 0"/>
    <parent link="LH_HIP"/>
    <child link="LH_HIPFixed"/>
  </joint>
  <link name="LH_HIPFixed">
    <!-- <visual>
                <geometry>
                    <sphere radius="0.05"/>
                </geometry>
                <material name="red"/>
            </visual> -->
    <inertial>
      <origin rpy="0 0 0" xyz="0 0 0"/>
      <mass value="0.000001"/>
      <inertia ixx="0.00000001" ixy="0" ixz="0" iyy="0.00000001" iyz="0" izz="0.00000001"/>
    </inertial>
  </link>
  <joint name="LH_HFE" type="revolute">
    <origin rpy="0 0 1.57079632679" xyz="-0.0541 0.09355 0"/>
    <parent link="LH_HIP"/>
    <child link="LH_THIGH"/>
    <axis xyz="1 0 0"/>
    <dynamics damping="0" friction="0"/>
    <limit effort="33.5" lower="-1.3962634016" upper="4.18879020479" velocity="21"/>
  </joint>
  <link name="LH_THIGH">
    <visual>
      <origin rpy="0 0 0" xyz="0 0 0"/>
      <geometry>
        <mesh filename="package://freeAny_description/meshes/thigh.STL" scale="1 1 1"/>
      </geometry>
      <material name="grey_alpha"/>
    </visual>
    <collision>
      <origin rpy="0 1.57079632679 0" xyz="-0.01 0 0"/>
      <geometry>
        <cylinder length="0.041" radius="0.032"/>
      </geometry>
    </collision>
    <collision>
      <origin rpy="0 0 0" xyz="0 0 -0.1"/>
      <geometry>
        <box size="0.032 0.048 0.2"/>
      </geometry>
    </collision>
    <inertial>
      <origin rpy="0 0 0" xyz="-0.018971 -0.0001 -0.072708"/>
      <mass value="1.15"/>
      <inertia ixx="0.014724523" ixy="5.677e-06" ixz="6.2711e-05" iyy="0.015466921" iyz="7.296e-06" izz="0.001822592"/>
    </inertial>
  </link>
  <joint name="LH_KFE" type="revolute">
    <origin rpy="0 0 0" xyz="0.034 0 -0.2"/>
    <parent link="LH_THIGH"/>
    <child link="LH_SHANK"/>
    <axis xyz="1 0 0"/>
    <dynamics damping="0" friction="0"/>
    <limit effort="52" lower="-3.14159265359" upper="3.14159265359" velocity="13"/>
  </joint>
  <link name="LH_SHANK">
    <visual>
      <origin rpy="0 0 3.14159265359" xyz="0 0 0"/>
      <geometry>
        <mesh filename="package://freeAny_description/meshes/shank_Right.STL" scale="1 1 1"/>
      </geometry>
      <material name="grey"/>
    </visual>
    <collision>
      <origin rpy="0 0 0" xyz="0 0.048 0"/>
      <geometry>
        <box size="0.03 0.02 0.045"/>
      </geometry>
    </collision>
    <collision>
      <origin rpy="0 1.57079632679 0" xyz="0 0 0"/>
      <geometry>
        <cylinder length="0.03" radius="0.029"/>
      </geometry>
    </collision>
    <inertial>
      <origin rpy="0 0 0" xyz="-0.000781 0.029499 -0.004542"/>
      <mass value="0.085"/>
      <inertia ixx="0.000156178" ixy="-0.0" ixz="0.0" iyy="3.8653e-05" iyz="-1.8611e-05" izz="0.000133207"/>
    </inertial>
  </link>
  <joint name="shank_to_foot_LH" type="fixed">
    <origin rpy="0 0 -1.57079632679" xyz="0 0.031301 -0.24819"/>
    <parent link="LH_SHANK"/>
    <child link="LH_FOOT"/>
  </joint>
  <link name="LH_FOOT">
    <visual>
      <origin rpy="0 0 3.14159265359" xyz="0 0 0"/>
      <geometry>
        <mesh filename="package://freeAny_description/meshes/foot.STL" scale="1 1 1"/>
      </geometry>
      <material name="grey_alpha"/>
    </visual>
    <collision>
      <origin rpy="0 0 0" xyz="-0.008 0 0.017"/>
      <geometry>
        <sphere radius="0.02"/>
      </geometry>
    </collision>
    <collision>
      <origin rpy="0 0 0" xyz="-0.016 0 0.13125"/>
      <geometry>
        <cylinder length="0.21" radius="0.012"/>
      </geometry>
    </collision>
    <inertial>
      <origin rpy="0 0 0" xyz="-0.012 0 0.065"/>
      <mass value="0.077"/>
      <inertia ixx="0.00629115" ixy="-0.0" ixz="-7.2557e-50" iyy="0.000641223" iyz="0" izz="2.3963e-05"/>
    </inertial>
  </link>
  <gazebo reference="shank_to_foot_LH">
    <disableFixedJointLumping>true</disableFixedJointLumping>
  </gazebo>
  <transmission name="LH_HAA_tran">
    <type>transmission_interface/SimpleTransmission</type>
    <joint name="LH_HAA">
      <hardwareInterface>hardware_interface/EffortJointInterface</hardwareInterface>
    </joint>
    <actuator name="LH_HAA_motor">
      <hardwareInterface>hardware_interface/EffortJointInterface</hardwareInterface>
      <mechanicalReduction>1</mechanicalReduction>
    </actuator>
  </transmission>
  <transmission name="LH_Thigh_tran">
    <type>transmission_interface/SimpleTransmission</type>
    <joint name="LH_HFE">
      <hardwareInterface>hardware_interface/EffortJointInterface</hardwareInterface>
    </joint>
    <actuator name="LH_Thigh_motor">
      <hardwareInterface>hardware_interface/EffortJointInterface</hardwareInterface>
      <mechanicalReduction>1</mechanicalReduction>
    </actuator>
  </transmission>
  <transmission name="LH_Knee_tran">
    <type>transmission_interface/SimpleTransmission</type>
    <joint name="LH_KFE">
      <hardwareInterface>hardware_interface/EffortJointInterface</hardwareInterface>
    </joint>
    <actuator name="LH_Knee_motor">
      <hardwareInterface>hardware_interface/EffortJointInterface</hardwareInterface>
      <mechanicalReduction>1</mechanicalReduction>
    </actuator>
  </transmission>
  <joint name="RH_HAA" type="revolute">
    <origin rpy="0 0 0" xyz="-0.1756 -0.055 0"/>
    <parent link="base"/>
    <child link="RH_HIP"/>
    <axis xyz="1 0 0"/>
    <dynamics damping="0" friction="0"/>
    <limit effort="33.5" lower="-0.802851455917" upper="0.802851455917" velocity="21"/>
  </joint>
  <link name="RH_HIP">
    <visual>
      <origin rpy="0 0 3.14159265359" xyz="0 0 0"/>
      <geometry>
        <mesh filename="package://freeAny_description/meshes/HIP.STL" scale="1 1 1"/>
      </geometry>
      <material name="grey"/>
    </visual>
    <collision>
      <origin rpy="1.57079632679 0 0" xyz="0.0541 0 0"/>
      <geometry>
        <cylinder length="0.04" radius="0.046"/>
      </geometry>
    </collision>
    <inertial>
      <origin rpy="0 0 0" xyz="-0.042659 -0.0034843 -0.00035303"/>
      <mass value="0.715"/>
      <inertia ixx="0.000546211" ixy="0.000114344" ixz="1.0737e-05" iyy="0.002324487" iyz="-3.2554e-05" izz="0.002086762"/>
    </inertial>
  </link>
  <joint name="RH_HIPFix" type="fixed">
    <origin rpy="0 0 0" xyz="-0.08 -0.04 0"/>
    <parent link="RH_HIP"/>
    <child link="RH_HIPFixed"/>
  </joint>
  <link name="RH_HIPFixed">
    <!-- <visual>
                <geometry>
                    <sphere radius="0.05"/>
                </geometry>
                <material name="red"/>
            </visual> -->
    <inertial>
      <origin rpy="0 0 0" xyz="0 0 0"/>
      <mass value="0.000001"/>
      <inertia ixx="0.00000001" ixy="0" ixz="0" iyy="0.00000001" iyz="0" izz="0.00000001"/>
    </inertial>
  </link>
  <joint name="RH_HFE" type="revolute">
    <origin rpy="0 0 1.57079632679" xyz="-0.0541 -0.09355 0"/>
    <parent link="RH_HIP"/>
    <child link="RH_THIGH"/>
    <axis xyz="1 0 0"/>
    <dynamics damping="0" friction="0"/>
    <limit effort="33.5" lower="-4.18879020479" upper="1.3962634016" velocity="21"/>
  </joint>
  <link name="RH_THIGH">
    <visual>
      <origin rpy="0 0 3.14159265359" xyz="0 0 0"/>
      <geometry>
        <mesh filename="package://freeAny_description/meshes/thigh.STL" scale="1 1 1"/>
      </geometry>
      <material name="grey_alpha"/>
    </visual>
    <collision>
      <origin rpy="0 1.57079632679 0" xyz="0.01 0 0"/>
      <geometry>
        <cylinder length="0.041" radius="0.032"/>
      </geometry>
    </collision>
    <collision>
      <origin rpy="0 0 0" xyz="0 0 -0.1"/>
      <geometry>
        <box size="0.032 0.048 0.2"/>
      </geometry>
    </collision>
    <inertial>
      <origin rpy="0 0 0" xyz="0.018971 0.0001 -0.072708"/>
      <mass value="1.15"/>
      <inertia ixx="0.014724523" ixy="5.677e-06" ixz="-6.2711e-05" iyy="0.015466921" iyz="-7.296e-06" izz="0.001822592"/>
    </inertial>
  </link>
  <joint name="RH_KFE" type="revolute">
    <origin rpy="0 0 0" xyz="-0.034 0 -0.2"/>
    <parent link="RH_THIGH"/>
    <child link="RH_SHANK"/>
    <axis xyz="1 0 0"/>
    <dynamics damping="0" friction="0"/>
    <limit effort="52" lower="-3.14159265359" upper="3.14159265359" velocity="13"/>
  </joint>
  <link name="RH_SHANK">
    <visual>
      <origin rpy="0 0 3.14159265359" xyz="0 0 0"/>
      <geometry>
        <mesh filename="package://freeAny_description/meshes/shank_Left.STL" scale="1 1 1"/>
      </geometry>
      <material name="grey"/>
    </visual>
    <collision>
      <origin rpy="0 0 0" xyz="0 0.048 0"/>
      <geometry>
        <box size="0.03 0.02 0.045"/>
      </geometry>
    </collision>
    <collision>
      <origin rpy="0 1.57079632679 0" xyz="0 0 0"/>
      <geometry>
        <cylinder length="0.03" radius="0.029"/>
      </geometry>
    </collision>
    <inertial>
      <origin rpy="0 0 0" xyz="0.000781 0.029499 -0.004542"/>
      <mass value="0.085"/>
      <inertia ixx="0.000156178" ixy="0.0" ixz="-0.0" iyy="3.8653e-05" iyz="-1.8611e-05" izz="0.000133207"/>
    </inertial>
  </link>
  <joint name="shank_to_foot_RH" type="fixed">
    <origin rpy="0 0 -1.57079632679" xyz="0 0.031301 -0.24819"/>
    <parent link="RH_SHANK"/>
    <child link="RH_FOOT"/>
  </joint>
  <link name="RH_FOOT">
    <visual>
      <origin rpy="0 0 3.14159265359" xyz="0 0 0"/>
      <geometry>
        <mesh filename="package://freeAny_description/meshes/foot.STL" scale="1 1 1"/>
      </geometry>
      <material name="grey_alpha"/>
    </visual>
    <collision>
      <origin rpy="0 0 0" xyz="-0.008 0 0.017"/>
      <geometry>
        <sphere radius="0.02"/>
      </geometry>
    </collision>
    <collision>
      <origin rpy="0 0 0" xyz="-0.016 0 0.13125"/>
      <geometry>
        <cylinder length="0.21" radius="0.012"/>
      </geometry>
    </collision>
    <inertial>
      <origin rpy="0 0 0" xyz="-0.012 0 0.065"/>
      <mass value="0.077"/>
      <inertia ixx="0.00629115" ixy="-0.0" ixz="-7.2557e-50" iyy="0.000641223" iyz="0" izz="2.3963e-05"/>
    </inertial>
  </link>
  <gazebo reference="shank_to_foot_RH">
    <disableFixedJointLumping>true</disableFixedJointLumping>
  </gazebo>
  <transmission name="RH_HAA_tran">
    <type>transmission_interface/SimpleTransmission</type>
    <joint name="RH_HAA">
      <hardwareInterface>hardware_interface/EffortJointInterface</hardwareInterface>
    </joint>
    <actuator name="RH_HAA_motor">
      <hardwareInterface>hardware_interface/EffortJointInterface</hardwareInterface>
      <mechanicalReduction>1</mechanicalReduction>
    </actuator>
  </transmission>
  <transmission name="RH_Thigh_tran">
    <type>transmission_interface/SimpleTransmission</type>
    <joint name="RH_HFE">
      <hardwareInterface>hardware_interface/EffortJointInterface</hardwareInterface>
    </joint>
    <actuator name="RH_Thigh_motor">
      <hardwareInterface>hardware_interface/EffortJointInterface</hardwareInterface>
      <mechanicalReduction>1</mechanicalReduction>
    </actuator>
  </transmission>
  <transmission name="RH_Knee_tran">
    <type>transmission_interface/SimpleTransmission</type>
    <joint name="RH_KFE">
      <hardwareInterface>hardware_interface/EffortJointInterface</hardwareInterface>
    </joint>
    <actuator name="RH_Knee_motor">
      <hardwareInterface>hardware_interface/EffortJointInterface</hardwareInterface>
      <mechanicalReduction>1</mechanicalReduction>
    </actuator>
  </transmission>
</robot>

